<?xml version="1.0"?>

<robot name="sphero"
       xmlns:sensor="http://playerstage.sourceforge.net/gazebo/xmlschema/#sensor"
       xmlns:controller="http://playerstage.sourceforge.net/gazebo/xmlschema/#controller"
       xmlns:interface="http://playerstage.sourceforge.net/gazebo/xmlschema/#interface"
       xmlns:xacro="http://ros.org/wiki/xacro">

  <property name="M_PI" value="3.14159"/>
  <property name="SCALE" value="0.0254"/>




  <link name="base_link">
    <inertial>
      <mass value="0.5" />
      <origin xyz="0 0 0.0" />
      <inertia ixx="0.0" ixy="0.0" ixz="0.0"
         iyy="0.0" iyz="0.0" izz="0.0" />
    </inertial>
    <visual>
      <origin xyz=" 0 0 0" rpy="3.14 0 0" />
      <geometry>
        <sphere radius="0.0381"/>
      </geometry>
    </visual>
    <collision>
      <origin xyz="0.0 0.0 0.0" rpy="0 0 0" />
      <geometry>
        <sphere radius="0.0281"/>
      </geometry>
    </collision>
  </link>

  <joint name="shell_joint" type="floating">
    <origin xyz="0 0 0" rpy="0 0 0" />
    <parent link="base_link"/>
    <child link="shell" />
  </joint>

  <link name="shell">
    <inertial>
      <mass value="0.5" />
      <origin xyz="0 0 0.0" />
      <inertia ixx="0.0" ixy="0.0" ixz="0.0"
         iyy="0.0" iyz="0.0" izz="0.0" />
    </inertial>

    <visual>
      <origin xyz=" 0 0 0" rpy="3.14 0 0" />
      <geometry>
  <mesh filename="package://sphero_description/meshes/Sphero_Textured.dae" scale=" 1.3  1.3  1.3"/>
    <!-- <mesh filename="package://sphero_description/meshes/Sphero_Textured.dae" scale=" 0.0127 0.0127 0.0127"/> -->
      </geometry>
    </visual>

    <collision>
      <origin xyz="0.0 0.0 0.0" rpy="0 0 0" />
      <geometry>
        <sphere radius="0.0381"/>
        <!-- <sphere radius="0.0381"/> -->
      </geometry>
    </collision>
  </link>


</robot>
